{'dataset_name': 'COLLAB', 'seed': 777, 'num_workers': 1, 'cov_weight': 0.01, 'hyperparams': {'batch_size': 32, 'epochs': 1001, 'learning_rate': 0.002, 'step_size': 50, 'decay_rate': 0.75}, 'architecture': {'layers': 4, 'hidden': 128, 'pooling': 'add', 'JK': 'cat', 'nonlinear_conv': 'penalty', 'dropout': 0.5, 'BN': 'Y', 'exps': 2, 'aggr': 'add'}, 'commit_id': '2ba1fd7980dcfd6125964c280caf9ac16f267a5a', 'time_stamp': '1612233934', 'directory': '../../nlg_results/tu/board/'}
-------- FOLD0 DATASET=COLLAB, COMMIT_ID=2ba1fd7980dcfd6125964c280caf9ac16f267a5a
Traceback (most recent call last):
  File "/opt/conda/lib/python3.6/multiprocessing/resource_sharer.py", line 142, in _serve
    with self._listener.accept() as conn:
  File "/opt/conda/lib/python3.6/multiprocessing/connection.py", line 455, in accept
    deliver_challenge(c, self._authkey)
  File "/opt/conda/lib/python3.6/multiprocessing/connection.py", line 722, in deliver_challenge
    response = connection.recv_bytes(256)        # reject large message
  File "/opt/conda/lib/python3.6/multiprocessing/connection.py", line 216, in recv_bytes
    buf = self._recv_bytes(maxlength)
  File "/opt/conda/lib/python3.6/multiprocessing/connection.py", line 407, in _recv_bytes
    buf = self._recv(4)
  File "/opt/conda/lib/python3.6/multiprocessing/connection.py", line 379, in _recv
    chunk = read(handle, remaining)
ConnectionResetError: [Errno 104] Connection reset by peer
